<?xml version="1.0" encoding="UTF-8"?>
<testng-results skipped="0" failed="2" ignored="0" total="4" passed="2">
  <reporter-output>
  </reporter-output>
  <suite name="Default suite" duration-ms="27634" started-at="2020-09-05T14:56:47 BDT" finished-at="2020-09-05T14:57:15 BDT">
    <groups>
    </groups>
    <test name="Default test" duration-ms="27634" started-at="2020-09-05T14:56:47 BDT" finished-at="2020-09-05T14:57:15 BDT">
      <class name="UdemyTest">
        <test-method status="FAIL" signature="f()[pri:0, instance:UdemyTest@3224f60b]" name="f" duration-ms="14343" started-at="2020-09-05T14:56:47 BDT" finished-at="2020-09-05T14:57:02 BDT">
          <exception class="java.lang.AssertionError">
            <message>
              <![CDATA[expected [false] but found [true]]]>
            </message>
            <full-stacktrace>
              <![CDATA[java.lang.AssertionError: expected [false] but found [true]
at org.testng.Assert.fail(Assert.java:99)
at org.testng.Assert.failNotEquals(Assert.java:1037)
at org.testng.Assert.assertFalse(Assert.java:67)
at org.testng.Assert.assertFalse(Assert.java:77)
at UdemyTest.testSignUp(UdemyTest.java:152)
at UdemyTest.f(UdemyTest.java:33)
at sun.reflect.NativeMethodAccessorImpl.invoke0(Native Method)
at sun.reflect.NativeMethodAccessorImpl.invoke(NativeMethodAccessorImpl.java:62)
at sun.reflect.DelegatingMethodAccessorImpl.invoke(DelegatingMethodAccessorImpl.java:43)
at java.lang.reflect.Method.invoke(Method.java:498)
at org.testng.internal.MethodInvocationHelper.invokeMethod(MethodInvocationHelper.java:132)
at org.testng.internal.TestInvoker.invokeMethod(TestInvoker.java:599)
at org.testng.internal.TestInvoker.invokeTestMethod(TestInvoker.java:174)
at org.testng.internal.MethodRunner.runInSequence(MethodRunner.java:46)
at org.testng.internal.TestInvoker$MethodInvocationAgent.invoke(TestInvoker.java:822)
at org.testng.internal.TestInvoker.invokeTestMethods(TestInvoker.java:147)
at org.testng.internal.TestMethodWorker.invokeTestMethods(TestMethodWorker.java:146)
at org.testng.internal.TestMethodWorker.run(TestMethodWorker.java:128)
at java.util.ArrayList.forEach(ArrayList.java:1259)
at org.testng.TestRunner.privateRun(TestRunner.java:764)
at org.testng.TestRunner.run(TestRunner.java:585)
at org.testng.SuiteRunner.runTest(SuiteRunner.java:384)
at org.testng.SuiteRunner.runSequentially(SuiteRunner.java:378)
at org.testng.SuiteRunner.privateRun(SuiteRunner.java:337)
at org.testng.SuiteRunner.run(SuiteRunner.java:286)
at org.testng.SuiteRunnerWorker.runSuite(SuiteRunnerWorker.java:53)
at org.testng.SuiteRunnerWorker.run(SuiteRunnerWorker.java:96)
at org.testng.TestNG.runSuitesSequentially(TestNG.java:1218)
at org.testng.TestNG.runSuitesLocally(TestNG.java:1140)
at org.testng.TestNG.runSuites(TestNG.java:1069)
at org.testng.TestNG.run(TestNG.java:1037)
at org.testng.remote.AbstractRemoteTestNG.run(AbstractRemoteTestNG.java:115)
at org.testng.remote.RemoteTestNG.initAndRun(RemoteTestNG.java:251)
at org.testng.remote.RemoteTestNG.main(RemoteTestNG.java:77)
]]>
            </full-stacktrace>
          </exception> <!-- java.lang.AssertionError -->
          <reporter-output>
          </reporter-output>
        </test-method> <!-- f -->
        <test-method status="PASS" signature="testSignIn()[pri:0, instance:UdemyTest@3224f60b]" name="testSignIn" duration-ms="4111" started-at="2020-09-05T14:57:02 BDT" finished-at="2020-09-05T14:57:06 BDT">
          <reporter-output>
          </reporter-output>
        </test-method> <!-- testSignIn -->
        <test-method status="PASS" signature="testSignInWithIncorrectData()[pri:0, instance:UdemyTest@3224f60b]" name="testSignInWithIncorrectData" duration-ms="4251" started-at="2020-09-05T14:57:06 BDT" finished-at="2020-09-05T14:57:10 BDT">
          <reporter-output>
          </reporter-output>
        </test-method> <!-- testSignInWithIncorrectData -->
        <test-method status="FAIL" signature="testSignUp()[pri:0, instance:UdemyTest@3224f60b]" name="testSignUp" duration-ms="4886" started-at="2020-09-05T14:57:10 BDT" finished-at="2020-09-05T14:57:15 BDT">
          <exception class="java.lang.AssertionError">
            <message>
              <![CDATA[expected [false] but found [true]]]>
            </message>
            <full-stacktrace>
              <![CDATA[java.lang.AssertionError: expected [false] but found [true]
at org.testng.Assert.fail(Assert.java:99)
at org.testng.Assert.failNotEquals(Assert.java:1037)
at org.testng.Assert.assertFalse(Assert.java:67)
at org.testng.Assert.assertFalse(Assert.java:77)
at UdemyTest.testSignUp(UdemyTest.java:152)
at sun.reflect.NativeMethodAccessorImpl.invoke0(Native Method)
at sun.reflect.NativeMethodAccessorImpl.invoke(NativeMethodAccessorImpl.java:62)
at sun.reflect.DelegatingMethodAccessorImpl.invoke(DelegatingMethodAccessorImpl.java:43)
at java.lang.reflect.Method.invoke(Method.java:498)
at org.testng.internal.MethodInvocationHelper.invokeMethod(MethodInvocationHelper.java:132)
at org.testng.internal.TestInvoker.invokeMethod(TestInvoker.java:599)
at org.testng.internal.TestInvoker.invokeTestMethod(TestInvoker.java:174)
at org.testng.internal.MethodRunner.runInSequence(MethodRunner.java:46)
at org.testng.internal.TestInvoker$MethodInvocationAgent.invoke(TestInvoker.java:822)
at org.testng.internal.TestInvoker.invokeTestMethods(TestInvoker.java:147)
at org.testng.internal.TestMethodWorker.invokeTestMethods(TestMethodWorker.java:146)
at org.testng.internal.TestMethodWorker.run(TestMethodWorker.java:128)
at java.util.ArrayList.forEach(ArrayList.java:1259)
at org.testng.TestRunner.privateRun(TestRunner.java:764)
at org.testng.TestRunner.run(TestRunner.java:585)
at org.testng.SuiteRunner.runTest(SuiteRunner.java:384)
at org.testng.SuiteRunner.runSequentially(SuiteRunner.java:378)
at org.testng.SuiteRunner.privateRun(SuiteRunner.java:337)
at org.testng.SuiteRunner.run(SuiteRunner.java:286)
at org.testng.SuiteRunnerWorker.runSuite(SuiteRunnerWorker.java:53)
at org.testng.SuiteRunnerWorker.run(SuiteRunnerWorker.java:96)
at org.testng.TestNG.runSuitesSequentially(TestNG.java:1218)
at org.testng.TestNG.runSuitesLocally(TestNG.java:1140)
at org.testng.TestNG.runSuites(TestNG.java:1069)
at org.testng.TestNG.run(TestNG.java:1037)
at org.testng.remote.AbstractRemoteTestNG.run(AbstractRemoteTestNG.java:115)
at org.testng.remote.RemoteTestNG.initAndRun(RemoteTestNG.java:251)
at org.testng.remote.RemoteTestNG.main(RemoteTestNG.java:77)
]]>
            </full-stacktrace>
          </exception> <!-- java.lang.AssertionError -->
          <reporter-output>
          </reporter-output>
        </test-method> <!-- testSignUp -->
      </class> <!-- UdemyTest -->
    </test> <!-- Default test -->
  </suite> <!-- Default suite -->
</testng-results>
